#VRML_SIM R2019b utf8
WorldInfo {
}
Viewpoint {
  orientation 0.8192325993862067 0.5080360805912479 0.26600242277167696 5.123292624087405
  position -0.9587343749879116 3.431645379867361 1.6711780945849752
}
TexturedBackground {
}
RectangleArena {
  translation 0.001241 0 -0.183617
  floorTileSize 1 1
  floorAppearance PBRAppearance {
    baseColorMap ImageTexture {
      url [
        "C:/Users/USER/AppData/Local/Programs/Webots/projects/robots/lego/mindstorms/worlds/textures/line.png"
      ]
    }
    metalness 0
  }
}
Robot {
  translation 0.384789 0.03 -0.564672
  rotation 0 -1 0 1.446987
  children [
    Camera {
      translation 0 0.05 0.15
      rotation 1 0 0 -1.8325996938995748
    }
    DistanceSensor {
      translation -0.02 0 0.11
      rotation 0 0 1 -1.5707996938995747
      name "sensor1"
      rotationStep 0.261799
      type "infra-red"
    }
    DistanceSensor {
      translation 0.02 0 0.11
      rotation 0 0 1 -1.5707996938995747
      name "sensor2"
      type "infra-red"
    }
    DistanceSensor {
      translation 0 0 0.11
      rotation 0 0 1 -1.5707996938995747
      name "sensor3"
      type "infra-red"
    }
    DEF wheel1 HingeJoint {
      jointParameters HingeJointParameters {
        anchor 0.06 0 0.05
      }
      device [
        DEF wheel1 RotationalMotor {
          name "wheel1"
        }
      ]
      endPoint Solid {
        translation 0.06 1.3198722809494515e-05 0.049971517525033836
        rotation -0.05668595823729211 0.05668614910613312 0.9967815119865724 1.5740233667850743
        children [
          DEF wheel Shape {
            appearance PBRAppearance {
              baseColor 0 1 0
              roughness 1
              metalness 0
            }
            geometry Cylinder {
              height 0.008
              radius 0.03
            }
          }
        ]
        boundingObject USE wheel
        physics Physics {
        }
        rotationStep 0.261799
      }
    }
    DEF wheel2 HingeJoint {
      jointParameters HingeJointParameters {
        anchor -0.06 0 0.05
      }
      device [
        DEF wheel2 RotationalMotor {
          name "wheel2"
        }
      ]
      endPoint Solid {
        translation -0.06 0 0.05
        rotation -1.4239046986508293e-07 1.4239094930950724e-07 0.9999999999999796 1.570799693899595
        children [
          DEF wheel Shape {
            appearance PBRAppearance {
              baseColor 0 1 0
              roughness 1
              metalness 0
            }
            geometry Cylinder {
              height 0.008
              radius 0.03
            }
          }
        ]
        name "solid(1)"
        boundingObject USE wheel
        physics Physics {
        }
      }
    }
    DEF wheel3 HingeJoint {
      jointParameters HingeJointParameters {
        anchor 0.06 0 -0.05
      }
      device [
        DEF wheel3 RotationalMotor {
          name "wheel3"
        }
      ]
      endPoint Solid {
        translation 0.06 0 -0.05
        rotation -1.4239046986508293e-07 1.4239094930950724e-07 0.9999999999999796 1.570799693899595
        children [
          DEF wheel Shape {
            appearance PBRAppearance {
              baseColor 0 1 0
              roughness 1
              metalness 0
            }
            geometry Cylinder {
              height 0.008
              radius 0.03
            }
          }
        ]
        name "solid(2)"
        boundingObject USE wheel
        physics Physics {
        }
      }
    }
    DEF wheel4 HingeJoint {
      jointParameters HingeJointParameters {
        anchor -0.06 0 -0.05
      }
      device [
        DEF wheel4 RotationalMotor {
          name "wheel4"
        }
      ]
      endPoint DEF wheel4 Solid {
        translation -0.06 0 -0.05
        rotation -1.4239046986508293e-07 1.4239094930950724e-07 0.9999999999999796 1.570799693899595
        children [
          DEF wheel Shape {
            appearance PBRAppearance {
              baseColor 0 1 0
              roughness 1
              metalness 0
            }
            geometry Cylinder {
              height 0.008
              radius 0.03
            }
          }
        ]
        name "solid(3)"
        boundingObject USE wheel
        physics Physics {
        }
      }
    }
    DEF body Shape {
      appearance PBRAppearance {
        baseColor 1 0 0
        roughness 1
        metalness 0
      }
      geometry Box {
        size 0.1 0.04 0.2
      }
    }
  ]
  boundingObject USE body
  physics Physics {
    mass 8
  }
  controller "my_controller"
}
TexturedBackgroundLight {
}
